Workbook

Sheet Hipotesis
A1: CASO PRÁCTICO · PLANTA DE PREFABRICADOS
A2: Celdas azules: hipótesis editables. Euros nominales, sin IVA. Años completos.
A4: Terreno | B4: 800000
A5: Nave | B5: 2800000
A6: Maquinaria | B6: 7600000
A7: Moldes | B7: 600000
A8: Informática | B8: 200000
A9: Inversión fija total | B9: =SUM(B4:B8) -> 12000000
A10: Vida nave (años) | B10: 40
A11: Vida maquinaria (años) | B11: 10
A12: Vida moldes (años) | B12: 4
A13: Vida informática (años) | B13: 4
A14: Precio inicial (€/m²) | B14: 150
A15: Coste variable inicial (€/m²) | B15: 92
A16: Compras aplazables incluidas en coste (€/m²) | B16: 78
A17: Coste fijo inicial (€/año) | B17: 1600000
A18: Crecimiento precio | B18: 0.02
A19: Crecimiento coste variable | B19: 0.025
A20: Crecimiento coste fijo | B20: 0.02
A21: Días cobro clientes | B21: 60
... A32: Capacidad vendible (m²/año) | B32: 100000
A33: Reposición conjunta moldes + informática | B33: =B7+B8 -> 800000
A34: IVA máquina (ejemplo separado) | B34: 0.21
A35: Meses financiación IVA (hipótesis) | B35: 6
A36: Interés puente IVA | B36: 0.05
A38: Supuestos: empresa existente con beneficios suficientes para absorber resultados marginales negativos.
A39: IS pagado en el año del devengo: simplificación anual. IVA y saldos tributarios no incluidos en NOF.
A40: Reposiciones nominales constantes; al final de vida de moldes/informática, salvo cierre en año 10.
A41: Venta de activos y liquidación al año 10; recuperación íntegra NOF. Sin subvenciones ni inflación del CAPEX.
A42: La sensibilidad publicada está calculada con hipótesis base: se ofrece como referencia, no se recalcula.
A43: Mantener préstamo = 6 x principal anual si se cambia la financiación; comprobar saldo final.
A44: Mantener vidas útiles y calendario industrial si se quiere reproducir el artículo; cambios exigen revisar operación.

Sheet Modelo
A1: MODELO ANUAL · EUROS · IMPORTES SIN REDONDEAR
A2: Producción vendida editable en fila 4. Los flujos se sitúan a final de año. NOF inicial: stock pagado.
A3: Magnitud | B3: 0 | C3: 1 | D3: 2 | E3: 3 | F3: 4 | G3: 5 | H3: 6 | I3: 7 | J3: 8 | K3: 9 | L3: 10
A4: Ventas físicas (m²) | B4: 0 | C4: 60000 | D4: 70000 | E4: 80000 | F4: 85000 | G4: 85000 | H4: 85000 | I4: 85000 | J4: 85000 | K4: 85000 | L4: 85000
A5: Precio (€/m²) | B5: 0 | C5: =Hipotesis!$B$14*(1+Hipotesis!$B$18)^(C$3-1) -> 150 | D5: =Hipotesis!$B$14*(1+Hipotesis!$B$18)^(D$3-1) -> 153 | E5: =Hipotesis!$B$14*(1+Hipotesis!$B$18)^(E$3-1) -> 156.06 | F5: =Hipotesis!$B$14*(1+Hipotesis!$B$18)^(F$3-1) -> 159.1812 | G5: =Hipotesis!$B$14*(1+Hipotesis!$B$18)^(G$3-1) -> 162.36482 | H5: =Hipotesis!$B$14*(1+Hipotesis!$B$18)^(H$3-1) -> 165.61212 | I5: =Hipotesis!$B$14*(1+Hipotesis!$B$18)^(I$3-1) -> 168.92436 | J5: =Hipotesis!$B$14*(1+Hipotesis!$B$18)^(J$3-1) -> 172.30285 | ... L5: =Hipotesis!$B$14*(1+Hipotesis!$B$18)^(L$3-1) -> 179.26389
A6: Coste variable unitario | B6: 0 | C6: =Hipotesis!$B$15*(1+Hipotesis!$B$19)^(C$3-1) -> 92 | D6: =Hipotesis!$B$15*(1+Hipotesis!$B$19)^(D$3-1) -> 94.3 | E6: =Hipotesis!$B$15*(1+Hipotesis!$B$19)^(E$3-1) -> 96.6575 | F6: =Hipotesis!$B$15*(1+Hipotesis!$B$19)^(F$3-1) -> 99.073937 | G6: =Hipotesis!$B$15*(1+Hipotesis!$B$19)^(G$3-1) -> 101.55079 | H6: =Hipotesis!$B$15*(1+Hipotesis!$B$19)^(H$3-1) -> 104.08956 | I6: =Hipotesis!$B$15*(1+Hipotesis!$B$19)^(I$3-1) -> 106.69179 | J6: =Hipotesis!$B$15*(1+Hipotesis!$B$19)^(J$3-1) -> 109.35909 | ... L6: =Hipotesis!$B$15*(1+Hipotesis!$B$19)^(L$3-1) -> 114.89539
A7: Compras unitarias aplazables | B7: 0 | C7: =Hipotesis!$B$16*(1+Hipotesis!$B$19)^(C$3-1) -> 78 | D7: =Hipotesis!$B$16*(1+Hipotesis!$B$19)^(D$3-1) -> 79.95 | E7: =Hipotesis!$B$16*(1+Hipotesis!$B$19)^(E$3-1) -> 81.94875 | F7: =Hipotesis!$B$16*(1+Hipotesis!$B$19)^(F$3-1) -> 83.997469 | G7: =Hipotesis!$B$16*(1+Hipotesis!$B$19)^(G$3-1) -> 86.097405 | H7: =Hipotesis!$B$16*(1+Hipotesis!$B$19)^(H$3-1) -> 88.249841 | I7: =Hipotesis!$B$16*(1+Hipotesis!$B$19)^(I$3-1) -> 90.456087 | J7: =Hipotesis!$B$16*(1+Hipotesis!$B$19)^(J$3-1) -> 92.717489 | ... L7: =Hipotesis!$B$16*(1+Hipotesis!$B$19)^(L$3-1) -> 97.411312
A8: Coste fijo | B8: 0 | C8: =Hipotesis!$B$17*(1+Hipotesis!$B$20)^(C$3-1) -> 1600000 | D8: =Hipotesis!$B$17*(1+Hipotesis!$B$20)^(D$3-1) -> 1632000 | E8: =Hipotesis!$B$17*(1+Hipotesis!$B$20)^(E$3-1) -> 1664640 | F8: =Hipotesis!$B$17*(1+Hipotesis!$B$20)^(F$3-1) -> 1697932.8 | G8: =Hipotesis!$B$17*(1+Hipotesis!$B$20)^(G$3-1) -> 1731891.5 | H8: =Hipotesis!$B$17*(1+Hipotesis!$B$20)^(H$3-1) -> 1766529.3 | I8: =Hipotesis!$B$17*(1+Hipotesis!$B$20)^(I$3-1) -> 1801859.9 | J8: =Hipotesis!$B$17*(1+Hipotesis!$B$20)^(J$3-1) -> 1837897.1 | ... L8: =Hipotesis!$B$17*(1+Hipotesis!$B$20)^(L$3-1) -> 1912148.1
A9: Ingresos | B9: 0 | C9: =C4*C5 -> 9000000 | D9: =D4*D5 -> 10710000 | E9: =E4*E5 -> 12484800 | F9: =F4*F5 -> 13530402 | G9: =G4*G5 -> 13801010 | H9: =H4*H5 -> 14077030 | I9: =I4*I5 -> 14358571 | J9: =J4*J5 -> 14645742 | ... L9: =L4*L5 -> 15237430
A10: Coste variable total | B10: 0 | C10: =C4*C6 -> 5520000 | D10: =D4*D6 -> 6601000 | E10: =E4*E6 -> 7732600 | F10: =F4*F6 -> 8421284.7 | G10: =G4*G6 -> 8631816.8 | H10: =H4*H6 -> 8847612.2 | I10: =I4*I6 -> 9068802.5 | J10: =J4*J6 -> 9295522.6 | ... L10: =L4*L6 -> 9766108.4
A11: Compras (incluidas en coste variable) | B11: 0 | C11: =C4*C7 -> 4680000 | D11: =D4*D7 -> 5596500 | E11: =E4*E7 -> 6555900 | F11: =F4*F7 -> 7139784.8 | G11: =G4*G7 -> 7318279.5 | H11: =H4*H7 -> 7501236.5 | I11: =I4*I7 -> 7688767.4 | J11: =J4*J7 -> 7880986.5 | ... L11: =L4*L7 -> 8279961.5
A12: EBITDA | B12: 0 | C12: =C9-C10-C8 -> 1880000 | D12: =D9-D10-D8 -> 2477000 | E12: =E9-E10-E8 -> 3087560 | F12: =F9-F10-F8 -> 3411184.5 | G12: =G9-G10-G8 -> 3437301.8 | H12: =H9-H10-H8 -> 3462888.7 | I12: =I9-I10-I8 -> 3487908.4 | J12: =J9-J10-J8 -> 3512322.6 | ... L12: =L9-L10-L8 -> 3559173.7
A13: Amortización nave | B13: 0 | C13: =IF(C$3<=Hipotesis!$B$10,Hipotesis!$B$5/Hipotesis!$B$10,0) -> 70000 | D13: =IF(D$3<=Hipotesis!$B$10,Hipotesis!$B$5/Hipotesis!$B$10,0) -> 70000 | E13: =IF(E$3<=Hipotesis!$B$10,Hipotesis!$B$5/Hipotesis!$B$10,0) -> 70000 | F13: =IF(F$3<=Hipotesis!$B$10,Hipotesis!$B$5/Hipotesis!$B$10,0) -> 70000 | G13: =IF(G$3<=Hipotesis!$B$10,Hipotesis!$B$5/Hipotesis!$B$10,0) -> 70000 | H13: =IF(H$3<=Hipotesis!$B$10,Hipotesis!$B$5/Hipotesis!$B$10,0) -> 70000 | I13: =IF(I$3<=Hipotesis!$B$10,Hipotesis!$B$5/Hipotesis!$B$10,0) -> 70000 | J13: =IF(J$3<=Hipotesis!$B$10,Hipotesis!$B$5/Hipotesis!$B$10,0) -> 70000 | ... L13: =IF(L$3<=Hipotesis!$B$10,Hipotesis!$B$5/Hipotesis!$B$10,0) -> 70000
A14: Amortización maquinaria | B14: 0 | C14: =IF(C$3<=Hipotesis!$B$11,Hipotesis!$B$6/Hipotesis!$B$11,0) -> 760000 | D14: =IF(D$3<=Hipotesis!$B$11,Hipotesis!$B$6/Hipotesis!$B$11,0) -> 760000 | E14: =IF(E$3<=Hipotesis!$B$11,Hipotesis!$B$6/Hipotesis!$B$11,0) -> 760000 | F14: =IF(F$3<=Hipotesis!$B$11,Hipotesis!$B$6/Hipotesis!$B$11,0) -> 760000 | G14: =IF(G$3<=Hipotesis!$B$11,Hipotesis!$B$6/Hipotesis!$B$11,0) -> 760000 | H14: =IF(H$3<=Hipotesis!$B$11,Hipotesis!$B$6/Hipotesis!$B$11,0) -> 760000 | I14: =IF(I$3<=Hipotesis!$B$11,Hipotesis!$B$6/Hipotesis!$B$11,0) -> 760000 | J14: =IF(J$3<=Hipotesis!$B$11,Hipotesis!$B$6/Hipotesis!$B$11,0) -> 760000 | ... L14: =IF(L$3<=Hipotesis!$B$11,Hipotesis!$B$6/Hipotesis!$B$11,0) -> 760000
A15: Amortización moldes | B15: 0 | C15: =Hipotesis!$B$7/Hipotesis!$B$12 -> 150000 | D15: =Hipotesis!$B$7/Hipotesis!$B$12 -> 150000 | E15: =Hipotesis!$B$7/Hipotesis!$B$12 -> 150000 | F15: =Hipotesis!$B$7/Hipotesis!$B$12 -> 150000 | G15: =Hipotesis!$B$7/Hipotesis!$B$12 -> 150000 | H15: =Hipotesis!$B$7/Hipotesis!$B$12 -> 150000 | I15: =Hipotesis!$B$7/Hipotesis!$B$12 -> 150000 | J15: =Hipotesis!$B$7/Hipotesis!$B$12 -> 150000 | ... L15: =Hipotesis!$B$7/Hipotesis!$B$12 -> 150000
A16: Amortización informática | B16: 0 | C16: =Hipotesis!$B$8/Hipotesis!$B$13 -> 50000 | D16: =Hipotesis!$B$8/Hipotesis!$B$13 -> 50000 | E16: =Hipotesis!$B$8/Hipotesis!$B$13 -> 50000 | F16: =Hipotesis!$B$8/Hipotesis!$B$13 -> 50000 | G16: =Hipotesis!$B$8/Hipotesis!$B$13 -> 50000 | H16: =Hipotesis!$B$8/Hipotesis!$B$13 -> 50000 | I16: =Hipotesis!$B$8/Hipotesis!$B$13 -> 50000 | J16: =Hipotesis!$B$8/Hipotesis!$B$13 -> 50000 | ... L16: =Hipotesis!$B$8/Hipotesis!$B$13 -> 50000
A17: Amortización total | B17: 0 | C17: =SUM(C13:C16) -> 1030000 | D17: =SUM(D13:D16) -> 1030000 | E17: =SUM(E13:E16) -> 1030000 | F17: =SUM(F13:F16) -> 1030000 | G17: =SUM(G13:G16) -> 1030000 | H17: =SUM(H13:H16) -> 1030000 | I17: =SUM(I13:I16) -> 1030000 | J17: =SUM(J13:J16) -> 1030000 | ... L17: =SUM(L13:L16) -> 1030000
A18: EBIT | B18: 0 | C18: =C12-C17 -> 850000 | D18: =D12-D17 -> 1447000 | E18: =E12-E17 -> 2057560 | F18: =F12-F17 -> 2381184.5 | G18: =G12-G17 -> 2407301.8 | H18: =H12-H17 -> 2432888.7 | I18: =I12-I17 -> 2457908.4 | J18: =J12-J17 -> 2482322.6 | ... L18: =L12-L17 -> 2529173.7
A19: IS teórico sin deuda | B19: 0 | C19: =C18*Hipotesis!$B$24 -> 212500 | D19: =D18*Hipotesis!$B$24 -> 361750 | E19: =E18*Hipotesis!$B$24 -> 514390 | F19: =F18*Hipotesis!$B$24 -> 595296.13 | G19: =G18*Hipotesis!$B$24 -> 601825.44 | H19: =H18*Hipotesis!$B$24 -> 608222.18 | I19: =I18*Hipotesis!$B$24 -> 614477.11 | J19: =J18*Hipotesis!$B$24 -> 620580.65 | ... L19: =L18*Hipotesis!$B$24 -> 632293.43
A20: Clientes | B20: 0 | C20: =C9*Hipotesis!$B$21/365 -> 1479452.1 | D20: =D9*Hipotesis!$B$21/365 -> 1760547.9 | E20: =E9*Hipotesis!$B$21/365 -> 2052295.9 | F20: =F9*Hipotesis!$B$21/365 -> 2224175.7 | G20: =G9*Hipotesis!$B$21/365 -> 2268659.2 | H20: =H9*Hipotesis!$B$21/365 -> 2314032.4 | I20: =I9*Hipotesis!$B$21/365 -> 2360313 | J20: =J9*Hipotesis!$B$21/365 -> 2407519.3 | ... L20: =L9*Hipotesis!$B$21/365 -> 2504783.1
A21: Existencias materiales | B21: =C4*Hipotesis!B16*Hipotesis!B22/365 -> 384657.53 | C21: =C11*Hipotesis!$B$22/365 -> 384657.53 | D21: =D11*Hipotesis!$B$22/365 -> 459986.3 | E21: =E11*Hipotesis!$B$22/365 -> 538841.1 | F21: =F11*Hipotesis!$B$22/365 -> 586831.63 | G21: =G11*Hipotesis!$B$22/365 -> 601502.42 | H21: =H11*Hipotesis!$B$22/365 -> 616539.98 | I21: =I11*Hipotesis!$B$22/365 -> 631953.48 | J21: =J11*Hipotesis!$B$22/365 -> 647752.32 | ... L21: =L11*Hipotesis!$B$22/365 -> 680544.78
A22: Proveedores | B22: 0 | C22: =C11*Hipotesis!$B$23/365 -> 576986.3 | D22: =D11*Hipotesis!$B$23/365 -> 689979.45 | E22: =E11*Hipotesis!$B$23/365 -> 808261.64 | F22: =F11*Hipotesis!$B$23/365 -> 880247.45 | G22: =G11*Hipotesis!$B$23/365 -> 902253.63 | H22: =H11*Hipotesis!$B$23/365 -> 924809.97 | I22: =I11*Hipotesis!$B$23/365 -> 947930.22 | J22: =J11*Hipotesis!$B$23/365 -> 971628.48 | ... L22: =L11*Hipotesis!$B$23/365 -> 1020817.2
A23: NOF (antes de liquidación) | B23: =B21 -> 384657.53 | C23: =C20+C21-C22 -> 1287123.3 | D23: =D20+D21-D22 -> 1530554.8 | E23: =E20+E21-E22 -> 1782875.3 | F23: =F20+F21-F22 -> 1930759.9 | G23: =G20+G21-G22 -> 1967908 | H23: =H20+H21-H22 -> 2005762.4 | I23: =I20+I21-I22 -> 2044336.3 | J23: =J20+J21-J22 -> 2083643.1 | ... L23: =L20+L21-L22 -> 2164510.7
A24: Variación NOF | B24: 0 | C24: =C23-B23 -> 902465.75 | D24: =D23-C23 -> 243431.51 | E24: =E23-D23 -> 252320.55 | F24: =F23-E23 -> 147884.51 | G24: =G23-F23 -> 37148.118 | H24: =H23-G23 -> 37854.403 | I24: =I23-H23 -> 38573.898 | J24: =J23-I23 -> 39306.842 | ... L24: =L23-K23 -> 40814.067
A25: Inversión fija / reposiciones | B25: =Hipotesis!B9 -> 12000000 | C25: =IF(C$3<10,IF(MOD(C$3,Hipotesis!$B$12)=0,Hipotesis!$B$7,0)+IF(MOD(C$3,Hipotesis!$B$13)=0,Hipotesis!$B$8,0),0) -> 0 | D25: =IF(D$3<10,IF(MOD(D$3,Hipotesis!$B$12)=0,Hipotesis!$B$7,0)+IF(MOD(D$3,Hipotesis!$B$13)=0,Hipotesis!$B$8,0),0) -> 0 | E25: =IF(E$3<10,IF(MOD(E$3,Hipotesis!$B$12)=0,Hipotesis!$B$7,0)+IF(MOD(E$3,Hipotesis!$B$13)=0,Hipotesis!$B$8,0),0) -> 0 | F25: =IF(F$3<10,IF(MOD(F$3,Hipotesis!$B$12)=0,Hipotesis!$B$7,0)+IF(MOD(F$3,Hipotesis!$B$13)=0,Hipotesis!$B$8,0),0) -> 800000 | G25: =IF(G$3<10,IF(MOD(G$3,Hipotesis!$B$12)=0,Hipotesis!$B$7,0)+IF(MOD(G$3,Hipotesis!$B$13)=0,Hipotesis!$B$8,0),0) -> 0 | H25: =IF(H$3<10,IF(MOD(H$3,Hipotesis!$B$12)=0,Hipotesis!$B$7,0)+IF(MOD(H$3,Hipotesis!$B$13)=0,Hipotesis!$B$8,0),0) -> 0 | I25: =IF(I$3<10,IF(MOD(I$3,Hipotesis!$B$12)=0,Hipotesis!$B$7,0)+IF(MOD(I$3,Hipotesis!$B$13)=0,Hipotesis!$B$8,0),0) -> 0 | J25: =IF(J$3<10,IF(MOD(J$3,Hipotesis!$B$12)=0,Hipotesis!$B$7,0)+IF(MOD(J$3,Hipotesis!$B$13)=0,Hipotesis!$B$8,0),0) -> 800000 | ... L25: =IF(L$3<10,IF(MOD(L$3,Hipotesis!$B$12)=0,Hipotesis!$B$7,0)+IF(MOD(L$3,Hipotesis!$B$13)=0,Hipotesis!$B$8,0),0) -> 0
A26: Valor contable activos (antes de venta) | B26: =B25 -> 12000000 | C26: =B26+C25-C17 -> 10970000 | D26: =C26+D25-D17 -> 9940000 | E26: =D26+E25-E17 -> 8910000 | F26: =E26+F25-F17 -> 8680000 | G26: =F26+G25-G17 -> 7650000 | H26: =G26+H25-H17 -> 6620000 | I26: =H26+I25-I17 -> 5590000 | J26: =I26+J25-J17 -> 5360000 | ... L26: =K26+L25-L17 -> 3300000
A27: Cobro bruto venta activos | B27: 0 | C27: =IF(C$3=10,Hipotesis!$B$26,0) -> 0 | D27: =IF(D$3=10,Hipotesis!$B$26,0) -> 0 | E27: =IF(E$3=10,Hipotesis!$B$26,0) -> 0 | F27: =IF(F$3=10,Hipotesis!$B$26,0) -> 0 | G27: =IF(G$3=10,Hipotesis!$B$26,0) -> 0 | H27: =IF(H$3=10,Hipotesis!$B$26,0) -> 0 | I27: =IF(I$3=10,Hipotesis!$B$26,0) -> 0 | J27: =IF(J$3=10,Hipotesis!$B$26,0) -> 0 | ... L27: =IF(L$3=10,Hipotesis!$B$26,0) -> 3400000
A28: Coste salida | B28: 0 | C28: =IF(C$3=10,Hipotesis!$B$27,0) -> 0 | D28: =IF(D$3=10,Hipotesis!$B$27,0) -> 0 | E28: =IF(E$3=10,Hipotesis!$B$27,0) -> 0 | F28: =IF(F$3=10,Hipotesis!$B$27,0) -> 0 | G28: =IF(G$3=10,Hipotesis!$B$27,0) -> 0 | H28: =IF(H$3=10,Hipotesis!$B$27,0) -> 0 | I28: =IF(I$3=10,Hipotesis!$B$27,0) -> 0 | J28: =IF(J$3=10,Hipotesis!$B$27,0) -> 0 | ... L28: =IF(L$3=10,Hipotesis!$B$27,0) -> 150000
A29: Impuesto sobre resultado venta | B29: 0 | C29: =IF(C$3=10,(C27-C28-C26)*Hipotesis!$B$24,0) -> 0 | D29: =IF(D$3=10,(D27-D28-D26)*Hipotesis!$B$24,0) -> 0 | E29: =IF(E$3=10,(E27-E28-E26)*Hipotesis!$B$24,0) -> 0 | F29: =IF(F$3=10,(F27-F28-F26)*Hipotesis!$B$24,0) -> 0 | G29: =IF(G$3=10,(G27-G28-G26)*Hipotesis!$B$24,0) -> 0 | H29: =IF(H$3=10,(H27-H28-H26)*Hipotesis!$B$24,0) -> 0 | I29: =IF(I$3=10,(I27-I28-I26)*Hipotesis!$B$24,0) -> 0 | J29: =IF(J$3=10,(J27-J28-J26)*Hipotesis!$B$24,0) -> 0 | ... L29: =IF(L$3=10,(L27-L28-L26)*Hipotesis!$B$24,0) -> -12500
A30: Venta neta de coste e impuesto | B30: 0 | C30: =C27-C28-C29 -> 0 | D30: =D27-D28-D29 -> 0 | E30: =E27-E28-E29 -> 0 | F30: =F27-F28-F29 -> 0 | G30: =G27-G28-G29 -> 0 | H30: =H27-H28-H29 -> 0 | I30: =I27-I28-I29 -> 0 | J30: =J27-J28-J29 -> 0 | ... L30: =L27-L28-L29 -> 3262500
A31: Recuperación NOF al cierre | B31: 0 | C31: =IF(C$3=10,C23,0) -> 0 | D31: =IF(D$3=10,D23,0) -> 0 | E31: =IF(E$3=10,E23,0) -> 0 | F31: =IF(F$3=10,F23,0) -> 0 | G31: =IF(G$3=10,G23,0) -> 0 | H31: =IF(H$3=10,H23,0) -> 0 | I31: =IF(I$3=10,I23,0) -> 0 | J31: =IF(J$3=10,J23,0) -> 0 | ... L31: =IF(L$3=10,L23,0) -> 2164510.7
A32: Flujo libre del proyecto | B32: =-B25-B23 -> -12384658 | C32: =C12-C19-C24-C25+C30+C31 -> 765034.25 | D32: =D12-D19-D24-D25+D30+D31 -> 1871818.5 | E32: =E12-E19-E24-E25+E30+E31 -> 2320849.5 | F32: =F12-F19-F24-F25+F30+F31 -> 1868003.9 | G32: =G12-G19-G24-G25+G30+G31 -> 2798328.2 | H32: =H12-H19-H24-H25+H30+H31 -> 2816812.1 | I32: =I12-I19-I24-I25+I30+I31 -> 2834857.4 | J32: =J12-J19-J24-J25+J30+J31 -> 2052435.1 | ... L32: =L12-L19-L24-L25+L30+L31 -> 8313076.9
A33: Flujo actualizado al 10 % / tasa elegida | B33: =B32 -> -12384658 | C33: =C32/(1+Hipotesis!$B$25)^C$3 -> 695485.68 | D33: =D32/(1+Hipotesis!$B$25)^D$3 -> 1546957.4 | E33: =E32/(1+Hipotesis!$B$25)^E$3 -> 1743688.5 | F33: =F32/(1+Hipotesis!$B$25)^F$3 -> 1275871.8 | G33: =G32/(1+Hipotesis!$B$25)^G$3 -> 1737541.7 | H33: =H32/(1+Hipotesis!$B$25)^H$3 -> 1590017 | I33: =I32/(1+Hipotesis!$B$25)^I$3 -> 1454730.1 | J33: =J32/(1+Hipotesis!$B$25)^J$3 -> 957476.13 | ... L33: =L32/(1+Hipotesis!$B$25)^L$3 -> 3205051
A34: Acumulado sin descontar | B34: =B32 -> -12384658 | C34: =B34+C32 -> -11619623 | D34: =C34+D32 -> -9747804.8 | E34: =D34+E32 -> -7426955.3 | F34: =E34+F32 -> -5558951.5 | G34: =F34+G32 -> -2760623.3 | H34: =G34+H32 -> 56188.89 | I34: =H34+I32 -> 2891046.3 | J34: =I34+J32 -> 4943481.4 | ... L34: =K34+L32 -> 16126073
A35: Acumulado descontado | B35: =B33 -> -12384658 | C35: =B35+C33 -> -11689172 | D35: =C35+D33 -> -10142214 | E35: =D35+E33 -> -8398525.9 | F35: =E35+F33 -> -7122654.1 | G35: =F35+G33 -> -5385112.4 | H35: =G35+H33 -> -3795095.4 | I35: =H35+I33 -> -2340365.3 | J35: =I35+J33 -> -1382889.2 | ... L35: =K35+L33 -> 3039116.3
A36: Deuda al inicio | B36: 0 | C36: =B39 -> 6000000 | D36: =C39 -> 6000000 | E36: =D39 -> 5000000 | F36: =E39 -> 4000000 | G36: =F39 -> 3000000 | H36: =G39 -> 2000000 | I36: =H39 -> 1000000 | J36: =I39 -> 0 | ... L36: =K39 -> 0
A37: Intereses | B37: 0 | C37: =C36*Hipotesis!$B$29 -> 300000 | D37: =D36*Hipotesis!$B$29 -> 300000 | E37: =E36*Hipotesis!$B$29 -> 250000 | F37: =F36*Hipotesis!$B$29 -> 200000 | G37: =G36*Hipotesis!$B$29 -> 150000 | H37: =H36*Hipotesis!$B$29 -> 100000 | I37: =I36*Hipotesis!$B$29 -> 50000 | J37: =J36*Hipotesis!$B$29 -> 0 | ... L37: =L36*Hipotesis!$B$29 -> 0
A38: Devolución principal | B38: 0 | C38: =IF(AND(C$3>=2,C$3<=7),MIN(C36,Hipotesis!$B$30),0) -> 0 | D38: =IF(AND(D$3>=2,D$3<=7),MIN(D36,Hipotesis!$B$30),0) -> 1000000 | E38: =IF(AND(E$3>=2,E$3<=7),MIN(E36,Hipotesis!$B$30),0) -> 1000000 | F38: =IF(AND(F$3>=2,F$3<=7),MIN(F36,Hipotesis!$B$30),0) -> 1000000 | G38: =IF(AND(G$3>=2,G$3<=7),MIN(G36,Hipotesis!$B$30),0) -> 1000000 | H38: =IF(AND(H$3>=2,H$3<=7),MIN(H36,Hipotesis!$B$30),0) -> 1000000 | I38: =IF(AND(I$3>=2,I$3<=7),MIN(I36,Hipotesis!$B$30),0) -> 1000000 | J38: =IF(AND(J$3>=2,J$3<=7),MIN(J36,Hipotesis!$B$30),0) -> 0 | ... L38: =IF(AND(L$3>=2,L$3<=7),MIN(L36,Hipotesis!$B$30),0) -> 0
A39: Deuda al cierre | B39: =Hipotesis!B28 -> 6000000 | C39: =C36-C38 -> 6000000 | D39: =D36-D38 -> 5000000 | E39: =E36-E38 -> 4000000 | F39: =F36-F38 -> 3000000 | G39: =G36-G38 -> 2000000 | H39: =H36-H38 -> 1000000 | I39: =I36-I38 -> 0 | J39: =J36-J38 -> 0 | ... L39: =L36-L38 -> 0
A40: IS con deuda (explotación) | B40: 0 | C40: =(C18-C37)*Hipotesis!$B$24 -> 137500 | D40: =(D18-D37)*Hipotesis!$B$24 -> 286750 | E40: =(E18-E37)*Hipotesis!$B$24 -> 451890 | F40: =(F18-F37)*Hipotesis!$B$24 -> 545296.13 | G40: =(G18-G37)*Hipotesis!$B$24 -> 564325.44 | H40: =(H18-H37)*Hipotesis!$B$24 -> 583222.18 | I40: =(I18-I37)*Hipotesis!$B$24 -> 601977.11 | J40: =(J18-J37)*Hipotesis!$B$24 -> 620580.65 | ... L40: =(L18-L37)*Hipotesis!$B$24 -> 632293.43
...

Sheet Resultados
A1: LECTURA DE RESULTADOS
A3: VAN proyecto | B3: =SUM(Modelo!B33:L33) -> 3039116.3
A4: TIR proyecto | B4: =IRR(Modelo!B32:L32) -> 0.14181054
A5: TIR accionista | B5: =IRR(Modelo!B43:L43) -> 0.18934422
A6: VAN accionista a tasa indicada | B6: =SUM(Modelo!B44:L44) -> 999037.33
A7: DSCR mínimo | B7: =MIN(Modelo!C42:I42) -> 1.4975527
A8: Caja inicial necesaria (sin IVA/reserva) | B8: =-Modelo!B32 -> 12384658
A9: Aporte inicial accionista | B9: =-Modelo!B43 -> 6384657.5
A10: VAN sin venta neta (con recuperación NOF) | B10: =B3-Modelo!L30/(1+Hipotesis!B25)^10 -> 1781281.4
A11: Umbral contable año 1 (m²) | B11: =(Hipotesis!B17+Modelo!C17)/(Hipotesis!B14-Hipotesis!B15) -> 45344.828
A13: Payback simple base: 5,98 años; descontado: 9,15. Fracciones solo sobre caja operativa uniforme.
A14: El modelo anual concentra cobros al cierre: recuperación observada al final de años 6 y 10.
A16: LIQUIDEZ IVA · EJEMPLO SEPARADO (NO SUMADO AL VAN)
A17: IVA soportado en maquinaria | B17: =Hipotesis!B6*Hipotesis!B34 -> 1596000
A18: Interés bruto puente IVA | B18: =B17*Hipotesis!B36*Hipotesis!B35/12 -> 39900
A19: Ahorro IS sobre interés (supuesto deducible) | B19: =B18*Hipotesis!B24 -> 9975
A20: Coste neto puente IVA | B20: =B18-B19 -> 29925
A22: SENSIBILIDAD PUBLICADA · VALORES DE REFERENCIA, NO FÓRMULAS
A23: Ventas −15 % | B23: -121240.44
A24: Precio −10 % | B24: -2745783.1
A25: Coste variable +10 % | B25: -638878.55
A26: Inversión +15 % | B26: 1386218.7
A27: Cobro a 90 días | B27: 2495858.6
A28: Venta final −30 % | B28: 2744175.7
A29: Descuento al 12 % | B29: 1467281.1
A32: Comprobaciones: deuda final = 0; venta neta = 3.262.500; valor contable final = 3.300.000.
A34: Fuentes: BOE Ley 27/2014 arts. 11,12,16,29; RD 634/2015 arts. 3,4; PGC NRV 2ª.
A35: Supuestos docentes, no presupuestos de proveedores. Base legal consultada el 9 de octubre de 2026.
